<?xml version="1.0" encoding="UTF-8"?>
<testng-results skipped="0" failed="3" total="3" passed="0">
  <reporter-output>
  </reporter-output>
  <suite name="Default suite" duration-ms="33" started-at="2017-09-24T16:41:10Z" finished-at="2017-09-24T16:41:11Z">
    <groups>
    </groups>
    <test name="Default test" duration-ms="33" started-at="2017-09-24T16:41:10Z" finished-at="2017-09-24T16:41:11Z">
      <class name="BusinessScenarios_Component.zoloPart1Test">
        <test-method status="FAIL" signature="test1(java.util.Map)[pri:0, instance:BusinessScenarios_Component.zoloPart1Test@4883b407]" name="test1" duration-ms="0" started-at="2017-09-24T22:11:10Z" data-provider="dp_zolopart1test1" finished-at="2017-09-24T22:11:10Z">
          <exception class="org.testng.TestNGException">
            <message>
              <![CDATA[
Method public void BusinessScenarios_Component.zoloPart1Test.test1(java.util.Map) throws java.io.IOException requires a @DataProvider named : dp_zolopart1test1 in class DataProvider_Component.Dataprovider_testdata]]>
            </message>
            <full-stacktrace>
              <![CDATA[org.testng.TestNGException: 
Method public void BusinessScenarios_Component.zoloPart1Test.test1(java.util.Map) throws java.io.IOException requires a @DataProvider named : dp_zolopart1test1 in class DataProvider_Component.Dataprovider_testdata
	at org.testng.internal.Parameters.findDataProvider(Parameters.java:265)
	at org.testng.internal.Parameters.handleParameters(Parameters.java:414)
	at org.testng.internal.Invoker.handleParameters(Invoker.java:1383)
	at org.testng.internal.Invoker.createParameters(Invoker.java:1075)
	at org.testng.internal.Invoker.invokeTestMethods(Invoker.java:1180)
	at org.testng.internal.TestMethodWorker.invokeTestMethods(TestMethodWorker.java:127)
	at org.testng.internal.TestMethodWorker.run(TestMethodWorker.java:111)
	at org.testng.TestRunner.privateRun(TestRunner.java:767)
	at org.testng.TestRunner.run(TestRunner.java:617)
	at org.testng.SuiteRunner.runTest(SuiteRunner.java:334)
	at org.testng.SuiteRunner.runSequentially(SuiteRunner.java:329)
	at org.testng.SuiteRunner.privateRun(SuiteRunner.java:291)
	at org.testng.SuiteRunner.run(SuiteRunner.java:240)
	at org.testng.SuiteRunnerWorker.runSuite(SuiteRunnerWorker.java:52)
	at org.testng.SuiteRunnerWorker.run(SuiteRunnerWorker.java:86)
	at org.testng.TestNG.runSuitesSequentially(TestNG.java:1198)
	at org.testng.TestNG.runSuitesLocally(TestNG.java:1123)
	at org.testng.TestNG.run(TestNG.java:1031)
	at org.testng.remote.AbstractRemoteTestNG.run(AbstractRemoteTestNG.java:132)
	at org.testng.remote.RemoteTestNG.initAndRun(RemoteTestNG.java:230)
	at org.testng.remote.RemoteTestNG.main(RemoteTestNG.java:76)
]]>
            </full-stacktrace>
          </exception> <!-- org.testng.TestNGException -->
          <reporter-output>
          </reporter-output>
        </test-method> <!-- test1 -->
        <test-method status="FAIL" signature="test2(java.util.Map)[pri:0, instance:BusinessScenarios_Component.zoloPart1Test@4883b407]" name="test2" duration-ms="0" started-at="2017-09-24T22:11:10Z" data-provider="dp_zolopart1test" finished-at="2017-09-24T22:11:10Z">
          <exception class="org.testng.TestNGException">
            <message>
              <![CDATA[
Found two providers called 'dp_zolopart1test' on class DataProvider_Component.Dataprovider_testdata]]>
            </message>
            <full-stacktrace>
              <![CDATA[org.testng.TestNGException: 
Found two providers called 'dp_zolopart1test' on class DataProvider_Component.Dataprovider_testdata
	at org.testng.internal.Parameters.findDataProvider(Parameters.java:332)
	at org.testng.internal.Parameters.findDataProvider(Parameters.java:262)
	at org.testng.internal.Parameters.handleParameters(Parameters.java:414)
	at org.testng.internal.Invoker.handleParameters(Invoker.java:1383)
	at org.testng.internal.Invoker.createParameters(Invoker.java:1075)
	at org.testng.internal.Invoker.invokeTestMethods(Invoker.java:1180)
	at org.testng.internal.TestMethodWorker.invokeTestMethods(TestMethodWorker.java:127)
	at org.testng.internal.TestMethodWorker.run(TestMethodWorker.java:111)
	at org.testng.TestRunner.privateRun(TestRunner.java:767)
	at org.testng.TestRunner.run(TestRunner.java:617)
	at org.testng.SuiteRunner.runTest(SuiteRunner.java:334)
	at org.testng.SuiteRunner.runSequentially(SuiteRunner.java:329)
	at org.testng.SuiteRunner.privateRun(SuiteRunner.java:291)
	at org.testng.SuiteRunner.run(SuiteRunner.java:240)
	at org.testng.SuiteRunnerWorker.runSuite(SuiteRunnerWorker.java:52)
	at org.testng.SuiteRunnerWorker.run(SuiteRunnerWorker.java:86)
	at org.testng.TestNG.runSuitesSequentially(TestNG.java:1198)
	at org.testng.TestNG.runSuitesLocally(TestNG.java:1123)
	at org.testng.TestNG.run(TestNG.java:1031)
	at org.testng.remote.AbstractRemoteTestNG.run(AbstractRemoteTestNG.java:132)
	at org.testng.remote.RemoteTestNG.initAndRun(RemoteTestNG.java:230)
	at org.testng.remote.RemoteTestNG.main(RemoteTestNG.java:76)
]]>
            </full-stacktrace>
          </exception> <!-- org.testng.TestNGException -->
          <reporter-output>
          </reporter-output>
        </test-method> <!-- test2 -->
        <test-method status="FAIL" signature="test3(java.util.Map)[pri:0, instance:BusinessScenarios_Component.zoloPart1Test@4883b407]" name="test3" duration-ms="0" started-at="2017-09-24T22:11:11Z" data-provider="dp_zolopart1test" finished-at="2017-09-24T22:11:11Z">
          <exception class="org.testng.TestNGException">
            <message>
              <![CDATA[
Found two providers called 'dp_zolopart1test' on class DataProvider_Component.Dataprovider_testdata]]>
            </message>
            <full-stacktrace>
              <![CDATA[org.testng.TestNGException: 
Found two providers called 'dp_zolopart1test' on class DataProvider_Component.Dataprovider_testdata
	at org.testng.internal.Parameters.findDataProvider(Parameters.java:332)
	at org.testng.internal.Parameters.findDataProvider(Parameters.java:262)
	at org.testng.internal.Parameters.handleParameters(Parameters.java:414)
	at org.testng.internal.Invoker.handleParameters(Invoker.java:1383)
	at org.testng.internal.Invoker.createParameters(Invoker.java:1075)
	at org.testng.internal.Invoker.invokeTestMethods(Invoker.java:1180)
	at org.testng.internal.TestMethodWorker.invokeTestMethods(TestMethodWorker.java:127)
	at org.testng.internal.TestMethodWorker.run(TestMethodWorker.java:111)
	at org.testng.TestRunner.privateRun(TestRunner.java:767)
	at org.testng.TestRunner.run(TestRunner.java:617)
	at org.testng.SuiteRunner.runTest(SuiteRunner.java:334)
	at org.testng.SuiteRunner.runSequentially(SuiteRunner.java:329)
	at org.testng.SuiteRunner.privateRun(SuiteRunner.java:291)
	at org.testng.SuiteRunner.run(SuiteRunner.java:240)
	at org.testng.SuiteRunnerWorker.runSuite(SuiteRunnerWorker.java:52)
	at org.testng.SuiteRunnerWorker.run(SuiteRunnerWorker.java:86)
	at org.testng.TestNG.runSuitesSequentially(TestNG.java:1198)
	at org.testng.TestNG.runSuitesLocally(TestNG.java:1123)
	at org.testng.TestNG.run(TestNG.java:1031)
	at org.testng.remote.AbstractRemoteTestNG.run(AbstractRemoteTestNG.java:132)
	at org.testng.remote.RemoteTestNG.initAndRun(RemoteTestNG.java:230)
	at org.testng.remote.RemoteTestNG.main(RemoteTestNG.java:76)
]]>
            </full-stacktrace>
          </exception> <!-- org.testng.TestNGException -->
          <reporter-output>
          </reporter-output>
        </test-method> <!-- test3 -->
      </class> <!-- BusinessScenarios_Component.zoloPart1Test -->
    </test> <!-- Default test -->
  </suite> <!-- Default suite -->
</testng-results>
