<?xml version="1.0" encoding="UTF-8"?>
<!-- Generated by org.testng.reporters.JUnitReportReporter -->
<testsuite hostname="SANJAYKALT-03" name="BusinessScenarios_Component.zoloPart1Test" tests="3" failures="3" timestamp="24 Sep 2017 16:41:11 GMT" time="0.000" errors="0">
  <testcase name="test1" time="0.000" classname="BusinessScenarios_Component.zoloPart1Test">
    <failure type="org.testng.TestNGException" message="
Method public void BusinessScenarios_Component.zoloPart1Test.test1(java.util.Map) throws java.io.IOException requires a @DataProvider named : dp_zolopart1test1 in class DataProvider_Component.Dataprovider_testdata">
      <![CDATA[org.testng.TestNGException: 
Method public void BusinessScenarios_Component.zoloPart1Test.test1(java.util.Map) throws java.io.IOException requires a @DataProvider named : dp_zolopart1test1 in class DataProvider_Component.Dataprovider_testdata
	at org.testng.internal.Parameters.findDataProvider(Parameters.java:265)
	at org.testng.internal.Parameters.handleParameters(Parameters.java:414)
	at org.testng.internal.Invoker.handleParameters(Invoker.java:1383)
	at org.testng.internal.Invoker.createParameters(Invoker.java:1075)
	at org.testng.internal.Invoker.invokeTestMethods(Invoker.java:1180)
	at org.testng.internal.TestMethodWorker.invokeTestMethods(TestMethodWorker.java:127)
	at org.testng.internal.TestMethodWorker.run(TestMethodWorker.java:111)
	at org.testng.TestRunner.privateRun(TestRunner.java:767)
	at org.testng.TestRunner.run(TestRunner.java:617)
	at org.testng.SuiteRunner.runTest(SuiteRunner.java:334)
	at org.testng.SuiteRunner.runSequentially(SuiteRunner.java:329)
	at org.testng.SuiteRunner.privateRun(SuiteRunner.java:291)
	at org.testng.SuiteRunner.run(SuiteRunner.java:240)
	at org.testng.SuiteRunnerWorker.runSuite(SuiteRunnerWorker.java:52)
	at org.testng.SuiteRunnerWorker.run(SuiteRunnerWorker.java:86)
	at org.testng.TestNG.runSuitesSequentially(TestNG.java:1198)
	at org.testng.TestNG.runSuitesLocally(TestNG.java:1123)
	at org.testng.TestNG.run(TestNG.java:1031)
	at org.testng.remote.AbstractRemoteTestNG.run(AbstractRemoteTestNG.java:132)
	at org.testng.remote.RemoteTestNG.initAndRun(RemoteTestNG.java:230)
	at org.testng.remote.RemoteTestNG.main(RemoteTestNG.java:76)
]]>
    </failure>
  </testcase> <!-- test1 -->
  <testcase name="test2" time="0.000" classname="BusinessScenarios_Component.zoloPart1Test">
    <failure type="org.testng.TestNGException" message="
Found two providers called &#039;dp_zolopart1test&#039; on class DataProvider_Component.Dataprovider_testdata">
      <![CDATA[org.testng.TestNGException: 
Found two providers called 'dp_zolopart1test' on class DataProvider_Component.Dataprovider_testdata
	at org.testng.internal.Parameters.findDataProvider(Parameters.java:332)
	at org.testng.internal.Parameters.findDataProvider(Parameters.java:262)
	at org.testng.internal.Parameters.handleParameters(Parameters.java:414)
	at org.testng.internal.Invoker.handleParameters(Invoker.java:1383)
	at org.testng.internal.Invoker.createParameters(Invoker.java:1075)
	at org.testng.internal.Invoker.invokeTestMethods(Invoker.java:1180)
	at org.testng.internal.TestMethodWorker.invokeTestMethods(TestMethodWorker.java:127)
	at org.testng.internal.TestMethodWorker.run(TestMethodWorker.java:111)
	at org.testng.TestRunner.privateRun(TestRunner.java:767)
	at org.testng.TestRunner.run(TestRunner.java:617)
	at org.testng.SuiteRunner.runTest(SuiteRunner.java:334)
	at org.testng.SuiteRunner.runSequentially(SuiteRunner.java:329)
	at org.testng.SuiteRunner.privateRun(SuiteRunner.java:291)
	at org.testng.SuiteRunner.run(SuiteRunner.java:240)
	at org.testng.SuiteRunnerWorker.runSuite(SuiteRunnerWorker.java:52)
	at org.testng.SuiteRunnerWorker.run(SuiteRunnerWorker.java:86)
	at org.testng.TestNG.runSuitesSequentially(TestNG.java:1198)
	at org.testng.TestNG.runSuitesLocally(TestNG.java:1123)
	at org.testng.TestNG.run(TestNG.java:1031)
	at org.testng.remote.AbstractRemoteTestNG.run(AbstractRemoteTestNG.java:132)
	at org.testng.remote.RemoteTestNG.initAndRun(RemoteTestNG.java:230)
	at org.testng.remote.RemoteTestNG.main(RemoteTestNG.java:76)
]]>
    </failure>
  </testcase> <!-- test2 -->
  <testcase name="test3" time="0.000" classname="BusinessScenarios_Component.zoloPart1Test">
    <failure type="org.testng.TestNGException" message="
Found two providers called &#039;dp_zolopart1test&#039; on class DataProvider_Component.Dataprovider_testdata">
      <![CDATA[org.testng.TestNGException: 
Found two providers called 'dp_zolopart1test' on class DataProvider_Component.Dataprovider_testdata
	at org.testng.internal.Parameters.findDataProvider(Parameters.java:332)
	at org.testng.internal.Parameters.findDataProvider(Parameters.java:262)
	at org.testng.internal.Parameters.handleParameters(Parameters.java:414)
	at org.testng.internal.Invoker.handleParameters(Invoker.java:1383)
	at org.testng.internal.Invoker.createParameters(Invoker.java:1075)
	at org.testng.internal.Invoker.invokeTestMethods(Invoker.java:1180)
	at org.testng.internal.TestMethodWorker.invokeTestMethods(TestMethodWorker.java:127)
	at org.testng.internal.TestMethodWorker.run(TestMethodWorker.java:111)
	at org.testng.TestRunner.privateRun(TestRunner.java:767)
	at org.testng.TestRunner.run(TestRunner.java:617)
	at org.testng.SuiteRunner.runTest(SuiteRunner.java:334)
	at org.testng.SuiteRunner.runSequentially(SuiteRunner.java:329)
	at org.testng.SuiteRunner.privateRun(SuiteRunner.java:291)
	at org.testng.SuiteRunner.run(SuiteRunner.java:240)
	at org.testng.SuiteRunnerWorker.runSuite(SuiteRunnerWorker.java:52)
	at org.testng.SuiteRunnerWorker.run(SuiteRunnerWorker.java:86)
	at org.testng.TestNG.runSuitesSequentially(TestNG.java:1198)
	at org.testng.TestNG.runSuitesLocally(TestNG.java:1123)
	at org.testng.TestNG.run(TestNG.java:1031)
	at org.testng.remote.AbstractRemoteTestNG.run(AbstractRemoteTestNG.java:132)
	at org.testng.remote.RemoteTestNG.initAndRun(RemoteTestNG.java:230)
	at org.testng.remote.RemoteTestNG.main(RemoteTestNG.java:76)
]]>
    </failure>
  </testcase> <!-- test3 -->
</testsuite> <!-- BusinessScenarios_Component.zoloPart1Test -->
